<?xml version="1.0" ?>
<!-- =================================================================================== -->
<!-- |    This document was autogenerated by xacro from /home/gauss/projects/personal_ws/src/kuka_coke_cell/kuka_coke_description/urdf/kuka_table_rviz.xacro | -->
<!-- |    EDITING THIS FILE BY HAND IS NOT RECOMMENDED                                 | -->
<!-- =================================================================================== -->
<robot name="kr_50_r2500">
    <link name="world" />
    <!-- -350° -->
    <!--  360°/s -->
    <link name="base_link">
        <inertial>
            <origin rpy="0 0 0" xyz="-0.080585 0.00067592 0.086754" />
            <mass value="30.385" />
            <inertia ixx="0.38941" ixy="0.0047083" ixz="0.060696" iyy="0.87424" iyz="-0.00029206" izz="1.0819" />
        </inertial>
        <visual>
            <origin rpy="0 0 0" xyz="0 0 0" />
            <geometry>
                <mesh filename="package://kr_50_r2500_description/meshes/base_link.STL" />
            </geometry>
            <material name="">
                <color rgba="0.79216 0.81961 0.93333 1" />
            </material>
        </visual>
        <collision>
            <origin rpy="0 0 0" xyz="0 0 0" />
            <geometry>
                <mesh filename="package://kr_50_r2500_description/meshes/base_link.STL" />
            </geometry>
        </collision>
    </link>
    <link name="link1">
        <inertial>
            <origin rpy="0 0 0" xyz="0.0600446329714386 0.0116665626627102 0.247062352627269" />
            <mass value="56.0953515273858" />
            <inertia ixx="1.7123503270672" ixy="0.020886843872196" ixz="-0.525246219592262" iyy="2.15349859010488" iyz="-0.031415061955379" izz="1.31690706549715" />
        </inertial>
        <visual>
            <origin rpy="0 0 0" xyz="0 0 0" />
            <geometry>
                <mesh filename="package://kr_50_r2500_description/meshes/link1.STL" />
            </geometry>
            <material name="">
                <color rgba="0.792156862745098 0.819607843137255 0.933333333333333 1" />
            </material>
        </visual>
        <collision>
            <origin rpy="0 0 0" xyz="0 0 0" />
            <geometry>
                <mesh filename="package://kr_50_r2500_description/meshes/link1.STL" />
            </geometry>
        </collision>
    </link>
    <joint name="joint1" type="revolute">
        <origin rpy="1.5708 0.009141 0" xyz="0 -0.17 0" />
        <parent link="base_link" />
        <child link="link1" />
        <axis xyz="0 0 -1" />
        <limit effort="10000" lower="-3.22886" upper="3.22886" velocity="3.05433" />
    </joint>
    <link name="link2">
        <inertial>
            <origin rpy="0 0 0" xyz="0.0040251350126134 -0.177497207044946 0.578963319749875" />
            <mass value="35.5942562362571" />
            <inertia ixx="4.47662495992728" ixy="-0.00203441583192867" ixz="0.0769841500591921" iyy="4.49958249588231" iyz="0.214283202316168" izz="0.238618624180958" />
        </inertial>
        <visual>
            <origin rpy="0 0 0" xyz="0 0 0" />
            <geometry>
                <mesh filename="package://kr_50_r2500_description/meshes/link2.STL" />
            </geometry>
            <material name="">
                <color rgba="0.792156862745098 0.819607843137255 0.933333333333333 1" />
            </material>
        </visual>
        <collision>
            <origin rpy="0 0 0" xyz="0 0 0" />
            <geometry>
                <mesh filename="package://kr_50_r2500_description/meshes/link2.STL" />
            </geometry>
        </collision>
    </link>
    <joint name="joint2" type="revolute">
        <origin rpy="0 1.557055  0" xyz="0.175 -0.074807 0.405" />
        <parent link="link1" />
        <child link="link2" />
        <axis xyz="0 1 0" />
        <limit effort="10000" lower="-3.05433" upper="1.0472" velocity="2.75762" />
    </joint>
    <link name="link3">
        <inertial>
            <origin rpy="0 0 0" xyz="0.0305175734183824 0.097105360534718 0.0162382856824868" />
            <mass value="36.6784876951283" />
            <inertia ixx="0.563908772434098" ixy="0.0648382829251099" ixz="-0.0822356915818992" iyy="0.7868662787778" iyz="0.00379928707270628" izz="1.01511384262152" />
        </inertial>
        <visual>
            <origin rpy="0 0 0" xyz="0 0 0" />
            <geometry>
                <mesh filename="package://kr_50_r2500_description/meshes/link3.STL" />
            </geometry>
            <material name="">
                <color rgba="0.792156862745098 0.819607843137255 0.933333333333333 1" />
            </material>
        </visual>
        <collision>
            <origin rpy="0 0 0" xyz="0 0 0" />
            <geometry>
                <mesh filename="package://kr_50_r2500_description/meshes/link3.STL" />
            </geometry>
        </collision>
    </link>
    <joint name="joint3" type="revolute">
        <origin rpy="0 -1.557055 0" xyz="0 0 1.29" />
        <parent link="link2" />
        <child link="link3" />
        <axis xyz="0 1 0" />
        <limit effort="10000" lower="-2.0944" upper="2.96706" velocity="3.05433" />
    </joint>
    <link name="link4">
        <inertial>
            <origin rpy="0 0 0" xyz="0.400085577392824 0.0280533450779974 -6.01461215805621E-05" />
            <mass value="15.1542881051753" />
            <inertia ixx="0.0701060691297577" ixy="-0.0990093812478981" ixz="0.00018489912158269" iyy="0.729933929975417" iyz="-2.55452640777306E-05" izz="0.748398699396793" />
        </inertial>
        <visual>
            <origin rpy="0 0 0" xyz="0 0 0" />
            <geometry>
                <mesh filename="package://kr_50_r2500_description/meshes/link4.STL" />
            </geometry>
            <material name="">
                <color rgba="0.792156862745098 0.819607843137255 0.933333333333333 1" />
            </material>
        </visual>
        <collision>
            <origin rpy="0 0 0" xyz="0 0 0" />
            <geometry>
                <mesh filename="package://kr_50_r2500_description/meshes/link4.STL" />
            </geometry>
        </collision>
    </link>
    <joint name="joint4" type="revolute">
        <origin rpy="0 0 0" xyz="0.32687 0.074807 0.05" />
        <parent link="link3" />
        <child link="link4" />
        <axis xyz="1 0 0" />
        <limit effort="10000" lower="-3.14159" upper="3.14159" velocity="4.36332" />
    </joint>
    <link name="link5">
        <inertial>
            <origin rpy="0 0 0" xyz="0.0348166227286741 -0.0333672873060013 -7.86869120463773E-05" />
            <mass value="5.17490767884354" />
            <inertia ixx="0.0198943557123769" ixy="-0.00379528838423929" ixz="-3.17734786601442E-05" iyy="0.0325404927644558" iyz="2.0392665049925E-05" izz="0.0334468145607699" />
        </inertial>
        <visual>
            <origin rpy="0 0 0" xyz="0 0 0" />
            <geometry>
                <mesh filename="package://kr_50_r2500_description/meshes/link5.STL" />
            </geometry>
            <material name="">
                <color rgba="0.792156862745098 0.819607843137255 0.933333333333333 1" />
            </material>
        </visual>
        <collision>
            <origin rpy="0 0 0" xyz="0 0 0" />
            <geometry>
                <mesh filename="package://kr_50_r2500_description/meshes/link5.STL" />
            </geometry>
        </collision>
    </link>
    <joint name="joint5" type="revolute">
        <origin rpy="0 -0.0 0" xyz="0.708131634616243 0 0" />
        <parent link="link4" />
        <child link="link5" />
        <axis xyz="0 1 0" />
        <limit effort="10000" lower="-2.18166" upper="2.18166" velocity="4.36332" />
    </joint>
    <link name="link6">
        <inertial>
            <origin rpy="0 0 0" xyz="0.0697663509698883 -2.97159715269453E-06 -4.15148219581329E-05" />
            <mass value="0.362972835401582" />
            <inertia ixx="0.000809216081686161" ixy="9.97029573660496E-10" ixz="2.41841688721677E-07" iyy="0.000440777200154296" iyz="1.15745872636665E-07" izz="0.000441694717362902" />
        </inertial>
        <visual>
            <origin rpy="0 0 0" xyz="0 0 0" />
            <geometry>
                <mesh filename="package://kr_50_r2500_description/meshes/link6.STL" />
            </geometry>
            <material name="">
                <color rgba="0.792156862745098 0.819607843137255 0.933333333333333 1" />
            </material>
        </visual>
        <collision>
            <origin rpy="0 0 0" xyz="0 0 0" />
            <geometry>
                <mesh filename="package://kr_50_r2500_description/meshes/link6.STL" />
            </geometry>
        </collision>
    </link>
    <joint name="joint6" type="revolute">
        <origin rpy="0 0 0" xyz="0.0966663727881543 0 0" />
        <parent link="link5" />
        <child link="link6" />
        <axis xyz="1 0 0" />
        <limit effort="10000" lower="-6.10865" upper="6.10865" velocity="6.28319" />
    </joint>
    <joint name="link6_to_flange" type="fixed">
        <origin rpy="0 1.57079632679 0" xyz="0.07 0 0" />
        <parent link="link6" />
        <child link="flange" />
    </joint>
    <link name="flange">
        <inertial>
            <origin rpy="0 0 0" xyz="0 0 0" />
            <mass value="0.01" />
            <inertia ixx="0.00001" ixy="0.00000" ixz="0.00000" iyy="0.00001" iyz="0.00000" izz="0.00000" />
        </inertial>
    </link>
    <transmission name="tran1">
        <type>transmission_interface/SimpleTransmission</type>
        <joint name="joint1">
            <hardwareInterface>hardware_interface/EffortJointInterface</hardwareInterface>
        </joint>
        <actuator name="motor1">
            <mechanicalReduction>1</mechanicalReduction>
            <hardwareInterface>hardware_interface/EffortJointInterface</hardwareInterface>
        </actuator>
    </transmission>
    <transmission name="tran2">
        <type>transmission_interface/SimpleTransmission</type>
        <joint name="joint2">
            <hardwareInterface>hardware_interface/EffortJointInterface</hardwareInterface>
        </joint>
        <actuator name="motor2">
            <mechanicalReduction>1</mechanicalReduction>
            <hardwareInterface>hardware_interface/EffortJointInterface</hardwareInterface>
        </actuator>
    </transmission>
    <transmission name="tran3">
        <type>transmission_interface/SimpleTransmission</type>
        <joint name="joint3">
            <hardwareInterface>hardware_interface/EffortJointInterface</hardwareInterface>
        </joint>
        <actuator name="motor3">
            <mechanicalReduction>1</mechanicalReduction>
            <hardwareInterface>hardware_interface/EffortJointInterface</hardwareInterface>
        </actuator>
    </transmission>
    <transmission name="tran4">
        <type>transmission_interface/SimpleTransmission</type>
        <joint name="joint4">
            <hardwareInterface>hardware_interface/EffortJointInterface</hardwareInterface>
        </joint>
        <actuator name="motor4">
            <mechanicalReduction>1</mechanicalReduction>
            <hardwareInterface>hardware_interface/EffortJointInterface</hardwareInterface>
        </actuator>
    </transmission>
    <transmission name="tran5">
        <type>transmission_interface/SimpleTransmission</type>
        <joint name="joint5">
            <hardwareInterface>hardware_interface/EffortJointInterface</hardwareInterface>
        </joint>
        <actuator name="motor5">
            <mechanicalReduction>1</mechanicalReduction>
            <hardwareInterface>hardware_interface/EffortJointInterface</hardwareInterface>
        </actuator>
    </transmission>
    <transmission name="tran6">
        <type>transmission_interface/SimpleTransmission</type>
        <joint name="joint6">
            <hardwareInterface>hardware_interface/EffortJointInterface</hardwareInterface>
        </joint>
        <actuator name="motor6">
            <mechanicalReduction>1</mechanicalReduction>
            <hardwareInterface>hardware_interface/EffortJointInterface</hardwareInterface>
        </actuator>
    </transmission>
    <joint name="world_to_base_link" type="fixed">
        <origin rpy="-1.57079632679 0 0" xyz="0 0 0" />
        <parent link="world" />
        <child link="base_link" />
    </joint>
    <link name="gripper_base">
        <inertial>
            <origin rpy="0 0 0" xyz="0 0 0" />
            <mass value="0.2" />
            <inertia ixx="0.001" ixy="0.0" ixz="0.0" iyy="0.001" iyz="0.0" izz="0.001" />
        </inertial>
        <visual>
            <origin rpy="0 0 0" xyz="0 0 0.025" />
            <geometry>
                <box size="0.1 0.05 0.05" />
            </geometry>
            <material name="aluminium">
                <color rgba="0.515625 0.52734375 0.53515625 1" />
            </material>
        </visual>
        <collision>
            <origin rpy="0 0 0" xyz="0 0 0.025" />
            <geometry>
                <box size="0.1 0.05 0.05" />
            </geometry>
            <material name="aluminium">
                <color rgba="0.515625 0.52734375 0.53515625 1" />
            </material>
        </collision>
    </link>
    <link name="open_tip" />
    <joint name="open_tip_joint" type="fixed">
        <origin rpy="0 0 0" xyz="0 0 0.13782116141076978" />
        <parent link="gripper_base" />
        <child link="open_tip" />
    </joint>
    <link name="closed_tip" />
    <joint name="closed_tip_joint" type="fixed">
        <origin rpy="0 0 0" xyz="0 0 0.14898979485566355" />
        <parent link="gripper_base" />
        <child link="closed_tip" />
    </joint>
    <link name="zero_pos_tip" />
    <joint name="zero_pos_tip_joint" type="fixed">
        <origin rpy="0 0 0" xyz="0 0 0.17" />
        <parent link="gripper_base" />
        <child link="zero_pos_tip" />
    </joint>
    <link name="right_crank">
        <inertial>
            <origin rpy="0 0 0" xyz="0 0 0" />
            <mass value="0.2" />
            <inertia ixx="0.001" ixy="0.0" ixz="0.0" iyy="0.001" iyz="0.0" izz="0.001" />
        </inertial>
        <visual>
            <origin rpy="0 0 0" xyz="0 0 0.035" />
            <geometry>
                <box size="0.01 0.05 0.07" />
            </geometry>
            <material name="aluminium">
                <color rgba="0.515625 0.52734375 0.53515625 1" />
            </material>
        </visual>
        <collision>
            <origin rpy="0 0 0" xyz="0 0 0.035" />
            <geometry>
                <box size="0.01 0.05 0.07" />
            </geometry>
            <material name="aluminium">
                <color rgba="0.515625 0.52734375 0.53515625 1" />
            </material>
        </collision>
    </link>
    <link name="right_external_crank">
        <inertial>
            <origin rpy="0 0 0" xyz="0 0 0" />
            <mass value="0.2" />
            <inertia ixx="0.001" ixy="0.0" ixz="0.0" iyy="0.001" iyz="0.0" izz="0.001" />
        </inertial>
        <visual>
            <origin rpy="0 0 0" xyz="0 0 0.035" />
            <geometry>
                <box size="0.01 0.05 0.07" />
            </geometry>
            <material name="aluminium">
                <color rgba="0.515625 0.52734375 0.53515625 1" />
            </material>
        </visual>
        <collision>
            <origin rpy="0 0 0" xyz="0 0 0.035" />
            <geometry>
                <box size="0.01 0.05 0.07" />
            </geometry>
            <material name="aluminium">
                <color rgba="0.515625 0.52734375 0.53515625 1" />
            </material>
        </collision>
    </link>
    <link name="right_rod">
        <inertial>
            <origin rpy="0 0 0" xyz="0 0 0" />
            <mass value="0.2" />
            <inertia ixx="0.001" ixy="0.0" ixz="0.0" iyy="0.001" iyz="0.0" izz="0.001" />
        </inertial>
        <visual>
            <origin rpy="0 0 0" xyz="0 0 0.025" />
            <geometry>
                <box size="0.01 0.05 0.05" />
            </geometry>
            <material name="aluminium">
                <color rgba="0.515625 0.52734375 0.53515625 1" />
            </material>
        </visual>
        <collision>
            <origin rpy="0 0 0" xyz="0 0 0.025" />
            <geometry>
                <box size="0.01 0.05 0.05" />
            </geometry>
            <material name="aluminium">
                <color rgba="0.515625 0.52734375 0.53515625 1" />
            </material>
        </collision>
    </link>
    <link name="right_base_rod">
        <inertial>
            <origin rpy="0 0 0" xyz="0 0 0" />
            <mass value="0.2" />
            <inertia ixx="0.001" ixy="0.0" ixz="0.0" iyy="0.001" iyz="0.0" izz="0.001" />
        </inertial>
        <visual>
            <origin rpy="0 0 0" xyz="0 0 0.025" />
            <geometry>
                <box size="0.01 0.05 0.05" />
            </geometry>
            <material name="aluminium">
                <color rgba="0.515625 0.52734375 0.53515625 1" />
            </material>
        </visual>
        <collision>
            <origin rpy="0 0 0" xyz="0 0 0.025" />
            <geometry>
                <box size="0.01 0.05 0.05" />
            </geometry>
            <material name="aluminium">
                <color rgba="0.515625 0.52734375 0.53515625 1" />
            </material>
        </collision>
    </link>
    <link name="right_phalanx">
        <inertial>
            <origin rpy="0 0 0" xyz="0 0 0" />
            <mass value="0.2" />
            <inertia ixx="0.001" ixy="0.0" ixz="0.0" iyy="0.001" iyz="0.0" izz="0.001" />
        </inertial>
        <visual>
            <origin rpy="0 0 0" xyz="0 0 0.025" />
            <geometry>
                <box size="0.01 0.05 0.05" />
            </geometry>
            <material name="aluminium">
                <color rgba="0.515625 0.52734375 0.53515625 1" />
            </material>
        </visual>
        <collision>
            <origin rpy="0 0 0" xyz="0 0 0.025" />
            <geometry>
                <box size="0.01 0.05 0.05" />
            </geometry>
            <material name="aluminium">
                <color rgba="0.515625 0.52734375 0.53515625 1" />
            </material>
        </collision>
    </link>
    <joint name="right_finger_joint" type="revolute">
        <origin rpy="0 0 0" xyz="0.055 0 0.05" />
        <parent link="gripper_base" />
        <child link="right_crank" />
        <axis xyz="0 1 0" />
        <limit effort="5" lower="-0.7956029534845354" upper="1" velocity="5.0" />
    </joint>
    <joint name="right_joint_2_5" type="fixed">
        <origin rpy="0 -1.5707963267948966 0" xyz="0 0 0" />
        <parent link="right_rod" />
        <child link="right_phalanx" />
        <axis xyz="0 1 0" />
    </joint>
    <joint name="right_joint_1_2" type="revolute">
        <origin rpy="0 1.5707963267948966 0" xyz="0 0 0.07" />
        <parent link="right_crank" />
        <child link="right_rod" />
        <axis xyz="0 1 0" />
        <limit effort="10" lower="-3.141592653589793" upper="3.141592653589793" velocity="2.0" />
        <mimic joint="right_finger_joint" multiplier="-1" offset="0" />
    </joint>
    <joint name="right_joint_2_3" type="revolute">
        <origin rpy="0 1.5707963267948966 0" xyz="0 0 0.05" />
        <parent link="right_rod" />
        <child link="right_external_crank" />
        <axis xyz="0 1 0" />
        <limit effort="10" lower="-3.141592653589793" upper="3.141592653589793" velocity="2.0" />
        <mimic joint="right_finger_joint" multiplier="1" offset="0" />
    </joint>
    <joint name="right_joint_3_4" type="revolute">
        <origin rpy="0 1.5707963267948966 0" xyz="0 0 0.07" />
        <parent link="right_external_crank" />
        <child link="right_base_rod" />
        <axis xyz="0 1 0" />
        <limit effort="10" lower="-3.141592653589793" upper="3.141592653589793" velocity="2.0" />
        <mimic joint="right_finger_joint" multiplier="-1" offset="0" />
    </joint>
    <!-- Add if to include this link only for rviz  -->
    <!-- <link name="${prefix}tip"/>
    <joint name="${prefix}tip_joint" type="fixed">
      <origin xyz="${-0.5*link_width} 0 ${phalanx_length}" rpy="0 0 0"/>
      <parent link="${prefix}phalanx" />
      <child link="${prefix}tip" />
    </joint> -->
    <!-- <gazebo>
      <joint name="${prefix}joint_4_1" type="revolute">
        <parent>${prefix}base_rod</parent>
        <child>${prefix}crank</child>
        <pose relative_to="${prefix}base_rod">0 0 ${rod_length}   0 ${pi/2} 0</pose>
        <axis>
          <xyz>0 1 0</xyz>
        </axis>
      </joint>

      <joint name="${prefix}joint_0_4" type="revolute">
        <parent>${base_name}</parent>
        <child>${prefix}base_rod</child>
        <pose relative_to="${base_name}">${(0.5*(base_x+link_width)+rod_length)*cos(rot_z)} 0 ${base_z} 0 0 ${rot_z}</pose>
        <axis>
          <xyz>0 1 0</xyz>
        </axis>
      </joint>
    </gazebo>

    <gazebo reference="${prefix}phalanx">
      <self_collide>1</self_collide>
      <kp>100000</kp>
      <kd>200</kd>
      <mu1>2</mu1>
      <mu2>2</mu2>
    </gazebo> -->
    <link name="left_crank">
        <inertial>
            <origin rpy="0 0 0" xyz="0 0 0" />
            <mass value="0.2" />
            <inertia ixx="0.001" ixy="0.0" ixz="0.0" iyy="0.001" iyz="0.0" izz="0.001" />
        </inertial>
        <visual>
            <origin rpy="0 0 0" xyz="0 0 0.035" />
            <geometry>
                <box size="0.01 0.05 0.07" />
            </geometry>
            <material name="aluminium">
                <color rgba="0.515625 0.52734375 0.53515625 1" />
            </material>
        </visual>
        <collision>
            <origin rpy="0 0 0" xyz="0 0 0.035" />
            <geometry>
                <box size="0.01 0.05 0.07" />
            </geometry>
            <material name="aluminium">
                <color rgba="0.515625 0.52734375 0.53515625 1" />
            </material>
        </collision>
    </link>
    <link name="left_external_crank">
        <inertial>
            <origin rpy="0 0 0" xyz="0 0 0" />
            <mass value="0.2" />
            <inertia ixx="0.001" ixy="0.0" ixz="0.0" iyy="0.001" iyz="0.0" izz="0.001" />
        </inertial>
        <visual>
            <origin rpy="0 0 0" xyz="0 0 0.035" />
            <geometry>
                <box size="0.01 0.05 0.07" />
            </geometry>
            <material name="aluminium">
                <color rgba="0.515625 0.52734375 0.53515625 1" />
            </material>
        </visual>
        <collision>
            <origin rpy="0 0 0" xyz="0 0 0.035" />
            <geometry>
                <box size="0.01 0.05 0.07" />
            </geometry>
            <material name="aluminium">
                <color rgba="0.515625 0.52734375 0.53515625 1" />
            </material>
        </collision>
    </link>
    <link name="left_rod">
        <inertial>
            <origin rpy="0 0 0" xyz="0 0 0" />
            <mass value="0.2" />
            <inertia ixx="0.001" ixy="0.0" ixz="0.0" iyy="0.001" iyz="0.0" izz="0.001" />
        </inertial>
        <visual>
            <origin rpy="0 0 0" xyz="0 0 0.025" />
            <geometry>
                <box size="0.01 0.05 0.05" />
            </geometry>
            <material name="aluminium">
                <color rgba="0.515625 0.52734375 0.53515625 1" />
            </material>
        </visual>
        <collision>
            <origin rpy="0 0 0" xyz="0 0 0.025" />
            <geometry>
                <box size="0.01 0.05 0.05" />
            </geometry>
            <material name="aluminium">
                <color rgba="0.515625 0.52734375 0.53515625 1" />
            </material>
        </collision>
    </link>
    <link name="left_base_rod">
        <inertial>
            <origin rpy="0 0 0" xyz="0 0 0" />
            <mass value="0.2" />
            <inertia ixx="0.001" ixy="0.0" ixz="0.0" iyy="0.001" iyz="0.0" izz="0.001" />
        </inertial>
        <visual>
            <origin rpy="0 0 0" xyz="0 0 0.025" />
            <geometry>
                <box size="0.01 0.05 0.05" />
            </geometry>
            <material name="aluminium">
                <color rgba="0.515625 0.52734375 0.53515625 1" />
            </material>
        </visual>
        <collision>
            <origin rpy="0 0 0" xyz="0 0 0.025" />
            <geometry>
                <box size="0.01 0.05 0.05" />
            </geometry>
            <material name="aluminium">
                <color rgba="0.515625 0.52734375 0.53515625 1" />
            </material>
        </collision>
    </link>
    <link name="left_phalanx">
        <inertial>
            <origin rpy="0 0 0" xyz="0 0 0" />
            <mass value="0.2" />
            <inertia ixx="0.001" ixy="0.0" ixz="0.0" iyy="0.001" iyz="0.0" izz="0.001" />
        </inertial>
        <visual>
            <origin rpy="0 0 0" xyz="0 0 0.025" />
            <geometry>
                <box size="0.01 0.05 0.05" />
            </geometry>
            <material name="aluminium">
                <color rgba="0.515625 0.52734375 0.53515625 1" />
            </material>
        </visual>
        <collision>
            <origin rpy="0 0 0" xyz="0 0 0.025" />
            <geometry>
                <box size="0.01 0.05 0.05" />
            </geometry>
            <material name="aluminium">
                <color rgba="0.515625 0.52734375 0.53515625 1" />
            </material>
        </collision>
    </link>
    <joint name="left_finger_joint" type="revolute">
        <origin rpy="0 0 3.141592653589793" xyz="-0.055 0 0.05" />
        <parent link="gripper_base" />
        <child link="left_crank" />
        <axis xyz="0 1 0" />
        <limit effort="5" lower="-0.7956029534845354" upper="1" velocity="5.0" />
        <mimic joint="right_finger_joint" multiplier="1" offset="0" />
    </joint>
    <joint name="left_joint_2_5" type="fixed">
        <origin rpy="0 -1.5707963267948966 0" xyz="0 0 0" />
        <parent link="left_rod" />
        <child link="left_phalanx" />
        <axis xyz="0 1 0" />
    </joint>
    <joint name="left_joint_1_2" type="revolute">
        <origin rpy="0 1.5707963267948966 0" xyz="0 0 0.07" />
        <parent link="left_crank" />
        <child link="left_rod" />
        <axis xyz="0 1 0" />
        <limit effort="10" lower="-3.141592653589793" upper="3.141592653589793" velocity="2.0" />
        <mimic joint="left_finger_joint" multiplier="-1" offset="0" />
    </joint>
    <joint name="left_joint_2_3" type="revolute">
        <origin rpy="0 1.5707963267948966 0" xyz="0 0 0.05" />
        <parent link="left_rod" />
        <child link="left_external_crank" />
        <axis xyz="0 1 0" />
        <limit effort="10" lower="-3.141592653589793" upper="3.141592653589793" velocity="2.0" />
        <mimic joint="left_finger_joint" multiplier="1" offset="0" />
    </joint>
    <joint name="left_joint_3_4" type="revolute">
        <origin rpy="0 1.5707963267948966 0" xyz="0 0 0.07" />
        <parent link="left_external_crank" />
        <child link="left_base_rod" />
        <axis xyz="0 1 0" />
        <limit effort="10" lower="-3.141592653589793" upper="3.141592653589793" velocity="2.0" />
        <mimic joint="left_finger_joint" multiplier="-1" offset="0" />
    </joint>
    <!-- Add if to include this link only for rviz  -->
    <!-- <link name="${prefix}tip"/>
    <joint name="${prefix}tip_joint" type="fixed">
      <origin xyz="${-0.5*link_width} 0 ${phalanx_length}" rpy="0 0 0"/>
      <parent link="${prefix}phalanx" />
      <child link="${prefix}tip" />
    </joint> -->
    <!-- <gazebo>
      <joint name="${prefix}joint_4_1" type="revolute">
        <parent>${prefix}base_rod</parent>
        <child>${prefix}crank</child>
        <pose relative_to="${prefix}base_rod">0 0 ${rod_length}   0 ${pi/2} 0</pose>
        <axis>
          <xyz>0 1 0</xyz>
        </axis>
      </joint>

      <joint name="${prefix}joint_0_4" type="revolute">
        <parent>${base_name}</parent>
        <child>${prefix}base_rod</child>
        <pose relative_to="${base_name}">${(0.5*(base_x+link_width)+rod_length)*cos(rot_z)} 0 ${base_z} 0 0 ${rot_z}</pose>
        <axis>
          <xyz>0 1 0</xyz>
        </axis>
      </joint>
    </gazebo>

    <gazebo reference="${prefix}phalanx">
      <self_collide>1</self_collide>
      <kp>100000</kp>
      <kd>200</kd>
      <mu1>2</mu1>
      <mu2>2</mu2>
    </gazebo> -->
    <transmission name="right_finger_joint_trans">
        <type>transmission_interface/SimpleTransmission</type>
        <joint name="right_finger_joint">
            <hardwareInterface>hardware_interface/EffortJointInterface</hardwareInterface>
        </joint>
        <actuator name="right_finger_joint_motor">
            <mechanicalReduction>1</mechanicalReduction>
            <hardwareInterface>hardware_interface/EffortJointInterface</hardwareInterface>
        </actuator>
    </transmission>
    <transmission name="left_finger_joint_trans">
        <type>transmission_interface/SimpleTransmission</type>
        <joint name="left_finger_joint">
            <hardwareInterface>hardware_interface/EffortJointInterface</hardwareInterface>
        </joint>
        <actuator name="left_finger_joint_motor">
            <mechanicalReduction>1</mechanicalReduction>
            <hardwareInterface>hardware_interface/EffortJointInterface</hardwareInterface>
        </actuator>
    </transmission>
    <joint name="gripper_joint" type="fixed">
        <origin rpy="0 0 0" xyz="0 0 0.018" />
        <parent link="flange" />
        <child link="gripper_base" />
    </joint>
    <joint name="table_fixed" type="fixed">
        <origin rpy="0 0 0" xyz="0 1.5 0" />
        <parent link="world" />
        <child link="table" />
    </joint>
    <link name="table">
        <inertial>
            <origin rpy="0 0 0" xyz="-0.080585 0.00067592 0.086754" />
            <mass value="30.385" />
            <inertia ixx="0.38941" ixy="0.0047083" ixz="0.060696" iyy="0.87424" iyz="-0.00029206" izz="1.0819" />
        </inertial>
        <visual>
            <origin rpy="0 0 0" xyz="0 0 0" />
            <geometry>
                <mesh filename="package://kuka_coke_description/meshes/table.stl" />
            </geometry>
            <material name="">
                <color rgba="0.79216 0.81961 0.93333 1" />
            </material>
        </visual>
        <collision>
            <origin rpy="0 0 0" xyz="0 0 0" />
            <geometry>
                <mesh filename="package://kuka_coke_description/meshes/table.stl" />
            </geometry>
        </collision>
    </link>
    <transmission name="trans_right_joint_1_2">
        <type>transmission_interface/SimpleTransmission</type>
        <joint name="right_joint_1_2">
            <hardwareInterface>hardware_interface/EffortJointInterface</hardwareInterface>
        </joint>
        <actuator name="right_joint_1_2_motor">
            <hardwareInterface>hardware_interface/EffortJointInterface</hardwareInterface>
            <mechanicalReduction>1</mechanicalReduction>
        </actuator>
    </transmission>
    <transmission name="trans_right_joint_2_3">
        <type>transmission_interface/SimpleTransmission</type>
        <joint name="right_joint_2_3">
            <hardwareInterface>hardware_interface/EffortJointInterface</hardwareInterface>
        </joint>
        <actuator name="right_joint_2_3_motor">
            <hardwareInterface>hardware_interface/EffortJointInterface</hardwareInterface>
            <mechanicalReduction>1</mechanicalReduction>
        </actuator>
    </transmission>
    <transmission name="trans_right_joint_3_4">
        <type>transmission_interface/SimpleTransmission</type>
        <joint name="right_joint_3_4">
            <hardwareInterface>hardware_interface/EffortJointInterface</hardwareInterface>
        </joint>
        <actuator name="right_joint_3_4_motor">
            <hardwareInterface>hardware_interface/EffortJointInterface</hardwareInterface>
            <mechanicalReduction>1</mechanicalReduction>
        </actuator>
    </transmission>
    <transmission name="trans_left_joint_1_2">
        <type>transmission_interface/SimpleTransmission</type>
        <joint name="left_joint_1_2">
            <hardwareInterface>hardware_interface/EffortJointInterface</hardwareInterface>
        </joint>
        <actuator name="left_joint_1_2_motor">
            <hardwareInterface>hardware_interface/EffortJointInterface</hardwareInterface>
            <mechanicalReduction>1</mechanicalReduction>
        </actuator>
    </transmission>
    <transmission name="trans_left_joint_2_3">
        <type>transmission_interface/SimpleTransmission</type>
        <joint name="left_joint_2_3">
            <hardwareInterface>hardware_interface/EffortJointInterface</hardwareInterface>
        </joint>
        <actuator name="left_joint_2_3_motor">
            <hardwareInterface>hardware_interface/EffortJointInterface</hardwareInterface>
            <mechanicalReduction>1</mechanicalReduction>
        </actuator>
    </transmission>
    <transmission name="trans_left_joint_3_4">
        <type>transmission_interface/SimpleTransmission</type>
        <joint name="left_joint_3_4">
            <hardwareInterface>hardware_interface/EffortJointInterface</hardwareInterface>
        </joint>
        <actuator name="left_joint_3_4_motor">
            <hardwareInterface>hardware_interface/EffortJointInterface</hardwareInterface>
            <mechanicalReduction>1</mechanicalReduction>
        </actuator>
    </transmission>
    <gazebo>
        <plugin name="gazebo_ros_control">
            <robotNamespace>/</robotNamespace>
        </plugin>
    </gazebo>
</robot>

